[2024-04-23T15:17:01.890+0000] {local_task_job_runner.py:120} INFO - ::group::Pre task execution logs
[2024-04-23T15:17:01.917+0000] {taskinstance.py:2073} INFO - Dependencies all met for dep_context=non-requeueable deps ti=<TaskInstance: model_pipeline.generate_report manual__2024-04-23T15:13:50.352085+00:00 [queued]>
[2024-04-23T15:17:01.929+0000] {taskinstance.py:2073} INFO - Dependencies all met for dep_context=requeueable deps ti=<TaskInstance: model_pipeline.generate_report manual__2024-04-23T15:13:50.352085+00:00 [queued]>
[2024-04-23T15:17:01.930+0000] {taskinstance.py:2303} INFO - Starting attempt 1 of 2
[2024-04-23T15:17:01.949+0000] {taskinstance.py:2327} INFO - Executing <Task(PythonOperator): generate_report> on 2024-04-23 15:13:50.352085+00:00
[2024-04-23T15:17:01.961+0000] {warnings.py:110} WARNING - /home/***/.local/lib/python3.12/site-packages/***/task/task_runner/standard_task_runner.py:61: DeprecationWarning: This process (pid=1279) is multi-threaded, use of fork() may lead to deadlocks in the child.
  pid = os.fork()

[2024-04-23T15:17:01.964+0000] {standard_task_runner.py:63} INFO - Started process 1288 to run task
[2024-04-23T15:17:01.964+0000] {standard_task_runner.py:90} INFO - Running: ['***', 'tasks', 'run', 'model_pipeline', 'generate_report', 'manual__2024-04-23T15:13:50.352085+00:00', '--job-id', '118', '--raw', '--subdir', 'DAGS_FOLDER/ml_pipeline_dag.py', '--cfg-path', '/tmp/tmpf1c5pg1q']
[2024-04-23T15:17:01.965+0000] {standard_task_runner.py:91} INFO - Job 118: Subtask generate_report
[2024-04-23T15:17:02.023+0000] {task_command.py:426} INFO - Running <TaskInstance: model_pipeline.generate_report manual__2024-04-23T15:13:50.352085+00:00 [running]> on host ec31c9b90297
[2024-04-23T15:17:02.142+0000] {taskinstance.py:2644} INFO - Exporting env vars: AIRFLOW_CTX_DAG_OWNER='***' AIRFLOW_CTX_DAG_ID='model_pipeline' AIRFLOW_CTX_TASK_ID='generate_report' AIRFLOW_CTX_EXECUTION_DATE='2024-04-23T15:13:50.352085+00:00' AIRFLOW_CTX_TRY_NUMBER='1' AIRFLOW_CTX_DAG_RUN_ID='manual__2024-04-23T15:13:50.352085+00:00'
[2024-04-23T15:17:02.145+0000] {taskinstance.py:430} INFO - ::endgroup::
[2024-04-23T15:17:02.169+0000] {taskinstance.py:441} INFO - ::group::Post task execution logs
[2024-04-23T15:17:02.170+0000] {taskinstance.py:2890} ERROR - Task failed with exception
Traceback (most recent call last):
  File "/home/airflow/.local/lib/python3.12/site-packages/airflow/models/taskinstance.py", line 465, in _execute_task
    result = _execute_callable(context=context, **execute_callable_kwargs)
             ^^^^^^^^^^^^^^^^^^^^^^^^^^^^^^^^^^^^^^^^^^^^^^^^^^^^^^^^^^^^^
  File "/home/airflow/.local/lib/python3.12/site-packages/airflow/models/taskinstance.py", line 432, in _execute_callable
    return execute_callable(context=context, **execute_callable_kwargs)
           ^^^^^^^^^^^^^^^^^^^^^^^^^^^^^^^^^^^^^^^^^^^^^^^^^^^^^^^^^^^^
  File "/home/airflow/.local/lib/python3.12/site-packages/airflow/models/baseoperator.py", line 400, in wrapper
    return func(self, *args, **kwargs)
           ^^^^^^^^^^^^^^^^^^^^^^^^^^^
  File "/home/airflow/.local/lib/python3.12/site-packages/airflow/operators/python.py", line 235, in execute
    return_value = self.execute_callable()
                   ^^^^^^^^^^^^^^^^^^^^^^^
  File "/home/airflow/.local/lib/python3.12/site-packages/airflow/operators/python.py", line 252, in execute_callable
    return self.python_callable(*self.op_args, **self.op_kwargs)
           ^^^^^^^^^^^^^^^^^^^^^^^^^^^^^^^^^^^^^^^^^^^^^^^^^^^^^
  File "/opt/airflow/dags/ml_pipeline_dag.py", line 120, in generate_report
    report = classification_report(y_test, y_pred, output_dict=True)
             ^^^^^^^^^^^^^^^^^^^^^^^^^^^^^^^^^^^^^^^^^^^^^^^^^^^^^^^
  File "/home/airflow/.local/lib/python3.12/site-packages/sklearn/utils/_param_validation.py", line 203, in wrapper
    validate_parameter_constraints(
  File "/home/airflow/.local/lib/python3.12/site-packages/sklearn/utils/_param_validation.py", line 95, in validate_parameter_constraints
    raise InvalidParameterError(
sklearn.utils._param_validation.InvalidParameterError: The 'y_true' parameter of classification_report must be an array-like or a sparse matrix. Got None instead.
[2024-04-23T15:17:02.184+0000] {taskinstance.py:1205} INFO - Marking task as UP_FOR_RETRY. dag_id=model_pipeline, task_id=generate_report, execution_date=20240423T151350, start_date=20240423T151701, end_date=20240423T151702
[2024-04-23T15:17:02.202+0000] {standard_task_runner.py:110} ERROR - Failed to execute job 118 for task generate_report (The 'y_true' parameter of classification_report must be an array-like or a sparse matrix. Got None instead.; 1288)
[2024-04-23T15:17:02.221+0000] {local_task_job_runner.py:240} INFO - Task exited with return code 1
[2024-04-23T15:17:02.240+0000] {taskinstance.py:3482} INFO - 0 downstream tasks scheduled from follow-on schedule check
[2024-04-23T15:17:02.243+0000] {local_task_job_runner.py:222} INFO - ::endgroup::
