[2024-04-27T20:43:09.086+0000] {local_task_job_runner.py:120} INFO - ::group::Pre task execution logs
[2024-04-27T20:43:09.159+0000] {taskinstance.py:2073} INFO - Dependencies all met for dep_context=non-requeueable deps ti=<TaskInstance: model_pipeline.evaluate_model manual__2024-04-27T20:36:39.709598+00:00 [queued]>
[2024-04-27T20:43:09.179+0000] {taskinstance.py:2073} INFO - Dependencies all met for dep_context=requeueable deps ti=<TaskInstance: model_pipeline.evaluate_model manual__2024-04-27T20:36:39.709598+00:00 [queued]>
[2024-04-27T20:43:09.182+0000] {taskinstance.py:2303} INFO - Starting attempt 1 of 2
[2024-04-27T20:43:09.219+0000] {taskinstance.py:2327} INFO - Executing <Task(PythonOperator): evaluate_model> on 2024-04-27 20:36:39.709598+00:00
[2024-04-27T20:43:09.249+0000] {warnings.py:110} WARNING - /home/***/.local/lib/python3.12/site-packages/***/task/task_runner/standard_task_runner.py:61: DeprecationWarning: This process (pid=226) is multi-threaded, use of fork() may lead to deadlocks in the child.
  pid = os.fork()

[2024-04-27T20:43:09.253+0000] {standard_task_runner.py:63} INFO - Started process 235 to run task
[2024-04-27T20:43:09.252+0000] {standard_task_runner.py:90} INFO - Running: ['***', 'tasks', 'run', 'model_pipeline', 'evaluate_model', 'manual__2024-04-27T20:36:39.709598+00:00', '--job-id', '166', '--raw', '--subdir', 'DAGS_FOLDER/ml_pipeline_dag.py', '--cfg-path', '/tmp/tmpx2v6rj88']
[2024-04-27T20:43:09.255+0000] {standard_task_runner.py:91} INFO - Job 166: Subtask evaluate_model
[2024-04-27T20:43:09.360+0000] {task_command.py:426} INFO - Running <TaskInstance: model_pipeline.evaluate_model manual__2024-04-27T20:36:39.709598+00:00 [running]> on host c4427bb7f712
[2024-04-27T20:43:09.667+0000] {taskinstance.py:2644} INFO - Exporting env vars: AIRFLOW_CTX_DAG_OWNER='***' AIRFLOW_CTX_DAG_ID='model_pipeline' AIRFLOW_CTX_TASK_ID='evaluate_model' AIRFLOW_CTX_EXECUTION_DATE='2024-04-27T20:36:39.709598+00:00' AIRFLOW_CTX_TRY_NUMBER='1' AIRFLOW_CTX_DAG_RUN_ID='manual__2024-04-27T20:36:39.709598+00:00'
[2024-04-27T20:43:09.671+0000] {taskinstance.py:430} INFO - ::endgroup::
[2024-04-27T20:43:14.320+0000] {warnings.py:110} WARNING - /home/***/.local/lib/python3.12/site-packages/sklearn/base.py:493: UserWarning: X does not have valid feature names, but RandomForestClassifier was fitted with feature names
  warnings.warn(

[2024-04-27T20:43:19.725+0000] {ml_pipeline_dag.py:118} INFO - Accuracy: 0.6409
Precision: 0.6259898864612156
Recall: 0.6679222233533544
F1 Score: 0.6462765957446809
[2024-04-27T20:43:19.732+0000] {taskinstance.py:441} INFO - ::group::Post task execution logs
[2024-04-27T20:43:19.734+0000] {taskinstance.py:2890} ERROR - Task failed with exception
Traceback (most recent call last):
  File "/home/airflow/.local/lib/python3.12/site-packages/airflow/models/taskinstance.py", line 465, in _execute_task
    result = _execute_callable(context=context, **execute_callable_kwargs)
             ^^^^^^^^^^^^^^^^^^^^^^^^^^^^^^^^^^^^^^^^^^^^^^^^^^^^^^^^^^^^^
  File "/home/airflow/.local/lib/python3.12/site-packages/airflow/models/taskinstance.py", line 432, in _execute_callable
    return execute_callable(context=context, **execute_callable_kwargs)
           ^^^^^^^^^^^^^^^^^^^^^^^^^^^^^^^^^^^^^^^^^^^^^^^^^^^^^^^^^^^^
  File "/home/airflow/.local/lib/python3.12/site-packages/airflow/models/baseoperator.py", line 400, in wrapper
    return func(self, *args, **kwargs)
           ^^^^^^^^^^^^^^^^^^^^^^^^^^^
  File "/home/airflow/.local/lib/python3.12/site-packages/airflow/operators/python.py", line 235, in execute
    return_value = self.execute_callable()
                   ^^^^^^^^^^^^^^^^^^^^^^^
  File "/home/airflow/.local/lib/python3.12/site-packages/airflow/operators/python.py", line 252, in execute_callable
    return self.python_callable(*self.op_args, **self.op_kwargs)
           ^^^^^^^^^^^^^^^^^^^^^^^^^^^^^^^^^^^^^^^^^^^^^^^^^^^^^
  File "/opt/airflow/dags/ml_pipeline_dag.py", line 120, in evaluate_model
    mlflow.start_run(run_id=run_id)
  File "/home/airflow/.local/lib/python3.12/site-packages/mlflow/tracking/fluent.py", line 322, in start_run
    _validate_run_id(existing_run_id)
  File "/home/airflow/.local/lib/python3.12/site-packages/mlflow/utils/validation.py", line 305, in _validate_run_id
    raise MlflowException(f"Invalid run ID: '{run_id}'", error_code=INVALID_PARAMETER_VALUE)
mlflow.exceptions.MlflowException: Invalid run ID: 'manual__2024-04-27T20:36:39.709598+00:00'
[2024-04-27T20:43:19.772+0000] {taskinstance.py:1205} INFO - Marking task as UP_FOR_RETRY. dag_id=model_pipeline, task_id=evaluate_model, execution_date=20240427T203639, start_date=20240427T204309, end_date=20240427T204319
[2024-04-27T20:43:19.816+0000] {standard_task_runner.py:110} ERROR - Failed to execute job 166 for task evaluate_model (Invalid run ID: 'manual__2024-04-27T20:36:39.709598+00:00'; 235)
[2024-04-27T20:43:19.955+0000] {local_task_job_runner.py:240} INFO - Task exited with return code 1
[2024-04-27T20:43:20.023+0000] {taskinstance.py:3482} INFO - 0 downstream tasks scheduled from follow-on schedule check
[2024-04-27T20:43:20.027+0000] {local_task_job_runner.py:222} INFO - ::endgroup::
