[2024-04-23T14:37:45.284+0000] {local_task_job_runner.py:120} INFO - ::group::Pre task execution logs
[2024-04-23T14:37:45.310+0000] {taskinstance.py:2073} INFO - Dependencies all met for dep_context=non-requeueable deps ti=<TaskInstance: model_pipeline.code_quality_check manual__2024-04-23T14:37:41.495316+00:00 [queued]>
[2024-04-23T14:37:45.319+0000] {taskinstance.py:2073} INFO - Dependencies all met for dep_context=requeueable deps ti=<TaskInstance: model_pipeline.code_quality_check manual__2024-04-23T14:37:41.495316+00:00 [queued]>
[2024-04-23T14:37:45.320+0000] {taskinstance.py:2303} INFO - Starting attempt 1 of 2
[2024-04-23T14:37:45.336+0000] {taskinstance.py:2327} INFO - Executing <Task(PythonOperator): code_quality_check> on 2024-04-23 14:37:41.495316+00:00
[2024-04-23T14:37:45.348+0000] {warnings.py:110} WARNING - /home/***/.local/lib/python3.12/site-packages/***/task/task_runner/standard_task_runner.py:61: DeprecationWarning: This process (pid=386) is multi-threaded, use of fork() may lead to deadlocks in the child.
  pid = os.fork()

[2024-04-23T14:37:45.349+0000] {standard_task_runner.py:90} INFO - Running: ['***', 'tasks', 'run', 'model_pipeline', 'code_quality_check', 'manual__2024-04-23T14:37:41.495316+00:00', '--job-id', '95', '--raw', '--subdir', 'DAGS_FOLDER/ml_pipeline_dag.py', '--cfg-path', '/tmp/tmp8c83str0']
[2024-04-23T14:37:45.350+0000] {standard_task_runner.py:63} INFO - Started process 395 to run task
[2024-04-23T14:37:45.351+0000] {standard_task_runner.py:91} INFO - Job 95: Subtask code_quality_check
[2024-04-23T14:37:45.407+0000] {task_command.py:426} INFO - Running <TaskInstance: model_pipeline.code_quality_check manual__2024-04-23T14:37:41.495316+00:00 [running]> on host ec31c9b90297
[2024-04-23T14:37:45.521+0000] {taskinstance.py:2644} INFO - Exporting env vars: AIRFLOW_CTX_DAG_OWNER='***' AIRFLOW_CTX_DAG_ID='model_pipeline' AIRFLOW_CTX_TASK_ID='code_quality_check' AIRFLOW_CTX_EXECUTION_DATE='2024-04-23T14:37:41.495316+00:00' AIRFLOW_CTX_TRY_NUMBER='1' AIRFLOW_CTX_DAG_RUN_ID='manual__2024-04-23T14:37:41.495316+00:00'
[2024-04-23T14:37:45.523+0000] {taskinstance.py:430} INFO - ::endgroup::
[2024-04-23T14:37:45.525+0000] {taskinstance.py:441} INFO - ::group::Post task execution logs
[2024-04-23T14:37:45.526+0000] {taskinstance.py:2890} ERROR - Task failed with exception
Traceback (most recent call last):
  File "/home/airflow/.local/lib/python3.12/site-packages/airflow/models/taskinstance.py", line 465, in _execute_task
    result = _execute_callable(context=context, **execute_callable_kwargs)
             ^^^^^^^^^^^^^^^^^^^^^^^^^^^^^^^^^^^^^^^^^^^^^^^^^^^^^^^^^^^^^
  File "/home/airflow/.local/lib/python3.12/site-packages/airflow/models/taskinstance.py", line 432, in _execute_callable
    return execute_callable(context=context, **execute_callable_kwargs)
           ^^^^^^^^^^^^^^^^^^^^^^^^^^^^^^^^^^^^^^^^^^^^^^^^^^^^^^^^^^^^
  File "/home/airflow/.local/lib/python3.12/site-packages/airflow/models/baseoperator.py", line 400, in wrapper
    return func(self, *args, **kwargs)
           ^^^^^^^^^^^^^^^^^^^^^^^^^^^
  File "/home/airflow/.local/lib/python3.12/site-packages/airflow/operators/python.py", line 235, in execute
    return_value = self.execute_callable()
                   ^^^^^^^^^^^^^^^^^^^^^^^
  File "/home/airflow/.local/lib/python3.12/site-packages/airflow/operators/python.py", line 252, in execute_callable
    return self.python_callable(*self.op_args, **self.op_kwargs)
           ^^^^^^^^^^^^^^^^^^^^^^^^^^^^^^^^^^^^^^^^^^^^^^^^^^^^^
  File "/opt/airflow/dags/ml_pipeline_dag.py", line 27, in code_quality_check
    result = subprocess.run(['flake8', __file__], stdout=subprocess.PIPE, stderr=subprocess.PIPE)
             ^^^^^^^^^^^^^^^^^^^^^^^^^^^^^^^^^^^^^^^^^^^^^^^^^^^^^^^^^^^^^^^^^^^^^^^^^^^^^^^^^^^^
  File "/usr/local/lib/python3.12/subprocess.py", line 548, in run
    with Popen(*popenargs, **kwargs) as process:
         ^^^^^^^^^^^^^^^^^^^^^^^^^^^
  File "/usr/local/lib/python3.12/subprocess.py", line 1026, in __init__
    self._execute_child(args, executable, preexec_fn, close_fds,
  File "/usr/local/lib/python3.12/subprocess.py", line 1953, in _execute_child
    raise child_exception_type(errno_num, err_msg, err_filename)
PermissionError: [Errno 13] Permission denied: 'flake8'
[2024-04-23T14:37:45.543+0000] {taskinstance.py:1205} INFO - Marking task as UP_FOR_RETRY. dag_id=model_pipeline, task_id=code_quality_check, execution_date=20240423T143741, start_date=20240423T143745, end_date=20240423T143745
[2024-04-23T14:37:45.561+0000] {standard_task_runner.py:110} ERROR - Failed to execute job 95 for task code_quality_check ([Errno 13] Permission denied: 'flake8'; 395)
[2024-04-23T14:37:45.608+0000] {local_task_job_runner.py:240} INFO - Task exited with return code 1
[2024-04-23T14:37:45.652+0000] {taskinstance.py:3482} INFO - 0 downstream tasks scheduled from follow-on schedule check
[2024-04-23T14:37:45.655+0000] {local_task_job_runner.py:222} INFO - ::endgroup::
