[2024-04-23T14:52:17.044+0000] {local_task_job_runner.py:120} INFO - ::group::Pre task execution logs
[2024-04-23T14:52:17.070+0000] {taskinstance.py:2073} INFO - Dependencies all met for dep_context=non-requeueable deps ti=<TaskInstance: model_pipeline.data_quality_check manual__2024-04-23T14:52:05.511455+00:00 [queued]>
[2024-04-23T14:52:17.082+0000] {taskinstance.py:2073} INFO - Dependencies all met for dep_context=requeueable deps ti=<TaskInstance: model_pipeline.data_quality_check manual__2024-04-23T14:52:05.511455+00:00 [queued]>
[2024-04-23T14:52:17.083+0000] {taskinstance.py:2303} INFO - Starting attempt 1 of 2
[2024-04-23T14:52:17.100+0000] {taskinstance.py:2327} INFO - Executing <Task(PythonOperator): data_quality_check> on 2024-04-23 14:52:05.511455+00:00
[2024-04-23T14:52:17.111+0000] {warnings.py:110} WARNING - /home/***/.local/lib/python3.12/site-packages/***/task/task_runner/standard_task_runner.py:61: DeprecationWarning: This process (pid=637) is multi-threaded, use of fork() may lead to deadlocks in the child.
  pid = os.fork()

[2024-04-23T14:52:17.113+0000] {standard_task_runner.py:63} INFO - Started process 646 to run task
[2024-04-23T14:52:17.113+0000] {standard_task_runner.py:90} INFO - Running: ['***', 'tasks', 'run', 'model_pipeline', 'data_quality_check', 'manual__2024-04-23T14:52:05.511455+00:00', '--job-id', '100', '--raw', '--subdir', 'DAGS_FOLDER/ml_pipeline_dag.py', '--cfg-path', '/tmp/tmp02npavtb']
[2024-04-23T14:52:17.115+0000] {standard_task_runner.py:91} INFO - Job 100: Subtask data_quality_check
[2024-04-23T14:52:17.171+0000] {task_command.py:426} INFO - Running <TaskInstance: model_pipeline.data_quality_check manual__2024-04-23T14:52:05.511455+00:00 [running]> on host ec31c9b90297
[2024-04-23T14:52:17.281+0000] {taskinstance.py:2644} INFO - Exporting env vars: AIRFLOW_CTX_DAG_OWNER='***' AIRFLOW_CTX_DAG_ID='model_pipeline' AIRFLOW_CTX_TASK_ID='data_quality_check' AIRFLOW_CTX_EXECUTION_DATE='2024-04-23T14:52:05.511455+00:00' AIRFLOW_CTX_TRY_NUMBER='1' AIRFLOW_CTX_DAG_RUN_ID='manual__2024-04-23T14:52:05.511455+00:00'
[2024-04-23T14:52:17.283+0000] {taskinstance.py:430} INFO - ::endgroup::
[2024-04-23T14:52:17.284+0000] {taskinstance.py:441} INFO - ::group::Post task execution logs
[2024-04-23T14:52:17.285+0000] {taskinstance.py:2890} ERROR - Task failed with exception
Traceback (most recent call last):
  File "/home/airflow/.local/lib/python3.12/site-packages/airflow/models/taskinstance.py", line 465, in _execute_task
    result = _execute_callable(context=context, **execute_callable_kwargs)
             ^^^^^^^^^^^^^^^^^^^^^^^^^^^^^^^^^^^^^^^^^^^^^^^^^^^^^^^^^^^^^
  File "/home/airflow/.local/lib/python3.12/site-packages/airflow/models/taskinstance.py", line 432, in _execute_callable
    return execute_callable(context=context, **execute_callable_kwargs)
           ^^^^^^^^^^^^^^^^^^^^^^^^^^^^^^^^^^^^^^^^^^^^^^^^^^^^^^^^^^^^
  File "/home/airflow/.local/lib/python3.12/site-packages/airflow/models/baseoperator.py", line 400, in wrapper
    return func(self, *args, **kwargs)
           ^^^^^^^^^^^^^^^^^^^^^^^^^^^
  File "/home/airflow/.local/lib/python3.12/site-packages/airflow/operators/python.py", line 235, in execute
    return_value = self.execute_callable()
                   ^^^^^^^^^^^^^^^^^^^^^^^
  File "/home/airflow/.local/lib/python3.12/site-packages/airflow/operators/python.py", line 252, in execute_callable
    return self.python_callable(*self.op_args, **self.op_kwargs)
           ^^^^^^^^^^^^^^^^^^^^^^^^^^^^^^^^^^^^^^^^^^^^^^^^^^^^^
  File "/opt/airflow/dags/ml_pipeline_dag.py", line 38, in data_quality_check
    df = context['task_instance'].xcom_pull(task_ids='load_data', key=df)
                                                                      ^^
UnboundLocalError: cannot access local variable 'df' where it is not associated with a value
[2024-04-23T14:52:17.298+0000] {taskinstance.py:1205} INFO - Marking task as UP_FOR_RETRY. dag_id=model_pipeline, task_id=data_quality_check, execution_date=20240423T145205, start_date=20240423T145217, end_date=20240423T145217
[2024-04-23T14:52:17.312+0000] {standard_task_runner.py:110} ERROR - Failed to execute job 100 for task data_quality_check (cannot access local variable 'df' where it is not associated with a value; 646)
[2024-04-23T14:52:17.330+0000] {local_task_job_runner.py:240} INFO - Task exited with return code 1
[2024-04-23T14:52:17.369+0000] {taskinstance.py:3482} INFO - 0 downstream tasks scheduled from follow-on schedule check
[2024-04-23T14:52:17.372+0000] {local_task_job_runner.py:222} INFO - ::endgroup::
