[2024-04-19T17:38:47.170+0000] {local_task_job_runner.py:120} INFO - ::group::Pre task execution logs
[2024-04-19T17:38:47.246+0000] {taskinstance.py:2073} INFO - Dependencies all met for dep_context=non-requeueable deps ti=<TaskInstance: model_pipeline.load_data manual__2024-04-19T17:38:30.572120+00:00 [queued]>
[2024-04-19T17:38:47.276+0000] {taskinstance.py:2073} INFO - Dependencies all met for dep_context=requeueable deps ti=<TaskInstance: model_pipeline.load_data manual__2024-04-19T17:38:30.572120+00:00 [queued]>
[2024-04-19T17:38:47.279+0000] {taskinstance.py:2303} INFO - Starting attempt 1 of 2
[2024-04-19T17:38:47.324+0000] {taskinstance.py:2327} INFO - Executing <Task(PythonOperator): load_data> on 2024-04-19 17:38:30.572120+00:00
[2024-04-19T17:38:47.355+0000] {warnings.py:110} WARNING - /home/***/.local/lib/python3.12/site-packages/***/task/task_runner/standard_task_runner.py:61: DeprecationWarning: This process (pid=82) is multi-threaded, use of fork() may lead to deadlocks in the child.
  pid = os.fork()

[2024-04-19T17:38:47.361+0000] {standard_task_runner.py:63} INFO - Started process 98 to run task
[2024-04-19T17:38:47.362+0000] {standard_task_runner.py:90} INFO - Running: ['***', 'tasks', 'run', 'model_pipeline', 'load_data', 'manual__2024-04-19T17:38:30.572120+00:00', '--job-id', '9', '--raw', '--subdir', 'DAGS_FOLDER/ml_pipeline_dag.py', '--cfg-path', '/tmp/tmp71eachnd']
[2024-04-19T17:38:47.365+0000] {standard_task_runner.py:91} INFO - Job 9: Subtask load_data
[2024-04-19T17:38:47.505+0000] {task_command.py:426} INFO - Running <TaskInstance: model_pipeline.load_data manual__2024-04-19T17:38:30.572120+00:00 [running]> on host ec31c9b90297
[2024-04-19T17:38:47.731+0000] {taskinstance.py:2644} INFO - Exporting env vars: AIRFLOW_CTX_DAG_OWNER='***' AIRFLOW_CTX_DAG_ID='model_pipeline' AIRFLOW_CTX_TASK_ID='load_data' AIRFLOW_CTX_EXECUTION_DATE='2024-04-19T17:38:30.572120+00:00' AIRFLOW_CTX_TRY_NUMBER='1' AIRFLOW_CTX_DAG_RUN_ID='manual__2024-04-19T17:38:30.572120+00:00'
[2024-04-19T17:38:47.734+0000] {taskinstance.py:430} INFO - ::endgroup::
[2024-04-19T17:38:47.740+0000] {taskinstance.py:441} INFO - ::group::Post task execution logs
[2024-04-19T17:38:47.742+0000] {taskinstance.py:2890} ERROR - Task failed with exception
Traceback (most recent call last):
  File "/home/airflow/.local/lib/python3.12/site-packages/airflow/models/taskinstance.py", line 465, in _execute_task
    result = _execute_callable(context=context, **execute_callable_kwargs)
             ^^^^^^^^^^^^^^^^^^^^^^^^^^^^^^^^^^^^^^^^^^^^^^^^^^^^^^^^^^^^^
  File "/home/airflow/.local/lib/python3.12/site-packages/airflow/models/taskinstance.py", line 432, in _execute_callable
    return execute_callable(context=context, **execute_callable_kwargs)
           ^^^^^^^^^^^^^^^^^^^^^^^^^^^^^^^^^^^^^^^^^^^^^^^^^^^^^^^^^^^^
  File "/home/airflow/.local/lib/python3.12/site-packages/airflow/models/baseoperator.py", line 400, in wrapper
    return func(self, *args, **kwargs)
           ^^^^^^^^^^^^^^^^^^^^^^^^^^^
  File "/home/airflow/.local/lib/python3.12/site-packages/airflow/operators/python.py", line 235, in execute
    return_value = self.execute_callable()
                   ^^^^^^^^^^^^^^^^^^^^^^^
  File "/home/airflow/.local/lib/python3.12/site-packages/airflow/operators/python.py", line 252, in execute_callable
    return self.python_callable(*self.op_args, **self.op_kwargs)
           ^^^^^^^^^^^^^^^^^^^^^^^^^^^^^^^^^^^^^^^^^^^^^^^^^^^^^
  File "/opt/airflow/dags/ml_pipeline_dag.py", line 18, in load_data
    df = pd.read_csv('.../data/processed/final_data.csv')
         ^^^^^^^^^^^^^^^^^^^^^^^^^^^^^^^^^^^^^^^^^^^^^^^^
  File "/home/airflow/.local/lib/python3.12/site-packages/pandas/io/parsers/readers.py", line 1026, in read_csv
    return _read(filepath_or_buffer, kwds)
           ^^^^^^^^^^^^^^^^^^^^^^^^^^^^^^^
  File "/home/airflow/.local/lib/python3.12/site-packages/pandas/io/parsers/readers.py", line 620, in _read
    parser = TextFileReader(filepath_or_buffer, **kwds)
             ^^^^^^^^^^^^^^^^^^^^^^^^^^^^^^^^^^^^^^^^^^
  File "/home/airflow/.local/lib/python3.12/site-packages/pandas/io/parsers/readers.py", line 1620, in __init__
    self._engine = self._make_engine(f, self.engine)
                   ^^^^^^^^^^^^^^^^^^^^^^^^^^^^^^^^^
  File "/home/airflow/.local/lib/python3.12/site-packages/pandas/io/parsers/readers.py", line 1880, in _make_engine
    self.handles = get_handle(
                   ^^^^^^^^^^^
  File "/home/airflow/.local/lib/python3.12/site-packages/pandas/io/common.py", line 873, in get_handle
    handle = open(
             ^^^^^
FileNotFoundError: [Errno 2] No such file or directory: '.../data/processed/final_data.csv'
[2024-04-19T17:38:47.777+0000] {taskinstance.py:1205} INFO - Marking task as UP_FOR_RETRY. dag_id=model_pipeline, task_id=load_data, execution_date=20240419T173830, start_date=20240419T173847, end_date=20240419T173847
[2024-04-19T17:38:47.842+0000] {standard_task_runner.py:110} ERROR - Failed to execute job 9 for task load_data ([Errno 2] No such file or directory: '.../data/processed/final_data.csv'; 98)
[2024-04-19T17:38:47.906+0000] {local_task_job_runner.py:240} INFO - Task exited with return code 1
[2024-04-19T17:38:47.966+0000] {taskinstance.py:3482} INFO - 0 downstream tasks scheduled from follow-on schedule check
[2024-04-19T17:38:47.971+0000] {local_task_job_runner.py:222} INFO - ::endgroup::
