[2024-04-23T15:32:12.807+0000] {local_task_job_runner.py:120} INFO - ::group::Pre task execution logs
[2024-04-23T15:32:12.835+0000] {taskinstance.py:2073} INFO - Dependencies all met for dep_context=non-requeueable deps ti=<TaskInstance: model_pipeline.evaluate_model manual__2024-04-23T15:29:08.574263+00:00 [queued]>
[2024-04-23T15:32:12.847+0000] {taskinstance.py:2073} INFO - Dependencies all met for dep_context=requeueable deps ti=<TaskInstance: model_pipeline.evaluate_model manual__2024-04-23T15:29:08.574263+00:00 [queued]>
[2024-04-23T15:32:12.847+0000] {taskinstance.py:2303} INFO - Starting attempt 1 of 2
[2024-04-23T15:32:12.865+0000] {taskinstance.py:2327} INFO - Executing <Task(PythonOperator): evaluate_model> on 2024-04-23 15:29:08.574263+00:00
[2024-04-23T15:32:12.875+0000] {warnings.py:110} WARNING - /home/***/.local/lib/python3.12/site-packages/***/task/task_runner/standard_task_runner.py:61: DeprecationWarning: This process (pid=1635) is multi-threaded, use of fork() may lead to deadlocks in the child.
  pid = os.fork()

[2024-04-23T15:32:12.878+0000] {standard_task_runner.py:63} INFO - Started process 1644 to run task
[2024-04-23T15:32:12.878+0000] {standard_task_runner.py:90} INFO - Running: ['***', 'tasks', 'run', 'model_pipeline', 'evaluate_model', 'manual__2024-04-23T15:29:08.574263+00:00', '--job-id', '127', '--raw', '--subdir', 'DAGS_FOLDER/ml_pipeline_dag.py', '--cfg-path', '/tmp/tmp_vmm36j9']
[2024-04-23T15:32:12.880+0000] {standard_task_runner.py:91} INFO - Job 127: Subtask evaluate_model
[2024-04-23T15:32:12.940+0000] {task_command.py:426} INFO - Running <TaskInstance: model_pipeline.evaluate_model manual__2024-04-23T15:29:08.574263+00:00 [running]> on host ec31c9b90297
[2024-04-23T15:32:13.057+0000] {taskinstance.py:2644} INFO - Exporting env vars: AIRFLOW_CTX_DAG_OWNER='***' AIRFLOW_CTX_DAG_ID='model_pipeline' AIRFLOW_CTX_TASK_ID='evaluate_model' AIRFLOW_CTX_EXECUTION_DATE='2024-04-23T15:29:08.574263+00:00' AIRFLOW_CTX_TRY_NUMBER='1' AIRFLOW_CTX_DAG_RUN_ID='manual__2024-04-23T15:29:08.574263+00:00'
[2024-04-23T15:32:13.059+0000] {taskinstance.py:430} INFO - ::endgroup::
[2024-04-23T15:32:14.828+0000] {warnings.py:110} WARNING - /home/***/.local/lib/python3.12/site-packages/sklearn/base.py:493: UserWarning: X does not have valid feature names, but RandomForestClassifier was fitted with feature names
  warnings.warn(

[2024-04-23T15:32:17.089+0000] {taskinstance.py:441} INFO - ::group::Post task execution logs
[2024-04-23T15:32:17.092+0000] {taskinstance.py:2890} ERROR - Task failed with exception
Traceback (most recent call last):
  File "/home/airflow/.local/lib/python3.12/site-packages/airflow/models/taskinstance.py", line 465, in _execute_task
    result = _execute_callable(context=context, **execute_callable_kwargs)
             ^^^^^^^^^^^^^^^^^^^^^^^^^^^^^^^^^^^^^^^^^^^^^^^^^^^^^^^^^^^^^
  File "/home/airflow/.local/lib/python3.12/site-packages/airflow/models/taskinstance.py", line 432, in _execute_callable
    return execute_callable(context=context, **execute_callable_kwargs)
           ^^^^^^^^^^^^^^^^^^^^^^^^^^^^^^^^^^^^^^^^^^^^^^^^^^^^^^^^^^^^
  File "/home/airflow/.local/lib/python3.12/site-packages/airflow/models/baseoperator.py", line 400, in wrapper
    return func(self, *args, **kwargs)
           ^^^^^^^^^^^^^^^^^^^^^^^^^^^
  File "/home/airflow/.local/lib/python3.12/site-packages/airflow/operators/python.py", line 235, in execute
    return_value = self.execute_callable()
                   ^^^^^^^^^^^^^^^^^^^^^^^
  File "/home/airflow/.local/lib/python3.12/site-packages/airflow/operators/python.py", line 252, in execute_callable
    return self.python_callable(*self.op_args, **self.op_kwargs)
           ^^^^^^^^^^^^^^^^^^^^^^^^^^^^^^^^^^^^^^^^^^^^^^^^^^^^^
  File "/opt/airflow/dags/ml_pipeline_dag.py", line 103, in evaluate_model
    context['task_instance'].xcom_push(key='y_pred', value=y_pred.to_list())
                                                           ^^^^^^^^^^^^^^
AttributeError: 'numpy.ndarray' object has no attribute 'to_list'. Did you mean: 'tolist'?
[2024-04-23T15:32:17.116+0000] {taskinstance.py:1205} INFO - Marking task as UP_FOR_RETRY. dag_id=model_pipeline, task_id=evaluate_model, execution_date=20240423T152908, start_date=20240423T153212, end_date=20240423T153217
[2024-04-23T15:32:17.136+0000] {standard_task_runner.py:110} ERROR - Failed to execute job 127 for task evaluate_model ('numpy.ndarray' object has no attribute 'to_list'; 1644)
[2024-04-23T15:32:17.212+0000] {local_task_job_runner.py:240} INFO - Task exited with return code 1
[2024-04-23T15:32:17.242+0000] {taskinstance.py:3482} INFO - 0 downstream tasks scheduled from follow-on schedule check
[2024-04-23T15:32:17.246+0000] {local_task_job_runner.py:222} INFO - ::endgroup::
